<?xml version="1.0" ?>
<robot name="car" xmlns:xacro="http://www.ros.org/wiki/xacro">

<xacro:include filename="$(find car)/urdf/materials.xacro" />
<xacro:include filename="$(find car)/urdf/car.trans" />
<xacro:include filename="$(find car)/urdf/car.gazebo" />
<xacro:include filename="$(find car)/urdf/car.plugin.xacro" />
<xacro:include filename="$(find car)/urdf/depth.plugin.xacro" />
<link name="base_link">
  <inertial>
    <origin xyz="0.5000181378162949 0.25000000000000006 0.2517249688727959" rpy="0 0 0"/>
    <mass value="1971.5261098530282"/>
    <inertia ixx="83.35609" iyy="206.212802" izz="204.780211" ixy="0.0" iyz="0.0" ixz="-0.007768"/>
  </inertial>
  <visual>
    <origin xyz="0 0 0" rpy="0 0 0"/>
    <geometry>
      <mesh filename="file://$(find car)/meshes/base_link.stl" scale="0.001 0.001 0.001"/>
    </geometry>
    <material name="silver"/>
  </visual>
  <collision>
    <origin xyz="0 0 0" rpy="0 0 0"/>
    <geometry>
      <mesh filename="file://$(find car)/meshes/base_link.stl" scale="0.001 0.001 0.001"/>
    </geometry>
  </collision>
</link>

<link name="Wheel_front_right_1">
  <inertial>
    <origin xyz="0.0 -0.05000000000000001 0.0" rpy="0 0 0"/>
    <mass value="98.6460093227195"/>
    <inertia ixx="1.068665" iyy="1.97292" izz="1.068665" ixy="-0.0" iyz="-0.0" ixz="0.0"/>
  </inertial>
  <visual>
    <origin xyz="-0.875 0.01 -0.15" rpy="0 0 0"/>
    <geometry>
      <mesh filename="file://$(find car)/meshes/Wheel_front_right_1.stl" scale="0.001 0.001 0.001"/>
    </geometry>
    <material name="silver"/>
  </visual>
  <collision>
    <origin xyz="-0.875 0.01 -0.15" rpy="0 0 0"/>
    <geometry>
      <mesh filename="file://$(find car)/meshes/Wheel_front_right_1.stl" scale="0.001 0.001 0.001"/>
    </geometry>
  </collision>
</link>

<link name="Wheel_front_left_1">
  <inertial>
    <origin xyz="0.0 0.050000000000000044 0.0" rpy="0 0 0"/>
    <mass value="98.6460093227195"/>
    <inertia ixx="1.068665" iyy="1.97292" izz="1.068665" ixy="0.0" iyz="0.0" ixz="0.0"/>
  </inertial>
  <visual>
    <origin xyz="-0.875 -0.51 -0.15" rpy="0 0 0"/>
    <geometry>
      <mesh filename="file://$(find car)/meshes/Wheel_front_left_1.stl" scale="0.001 0.001 0.001"/>
    </geometry>
    <material name="silver"/>
  </visual>
  <collision>
    <origin xyz="-0.875 -0.51 -0.15" rpy="0 0 0"/>
    <geometry>
      <mesh filename="file://$(find car)/meshes/Wheel_front_left_1.stl" scale="0.001 0.001 0.001"/>
    </geometry>
  </collision>
</link>

<link name="Wheel_back_left_1">
  <inertial>
    <origin xyz="-2.7755575615628914e-17 0.050000000000000155 0.0" rpy="0 0 0"/>
    <mass value="98.6460093227195"/>
    <inertia ixx="1.068665" iyy="1.97292" izz="1.068665" ixy="0.0" iyz="0.0" ixz="0.0"/>
  </inertial>
  <visual>
    <origin xyz="-0.15 -0.51 -0.15" rpy="0 0 0"/>
    <geometry>
      <mesh filename="file://$(find car)/meshes/Wheel_back_left_1.stl" scale="0.001 0.001 0.001"/>
    </geometry>
    <material name="silver"/>
  </visual>
  <collision>
    <origin xyz="-0.15 -0.51 -0.15" rpy="0 0 0"/>
    <geometry>
      <mesh filename="file://$(find car)/meshes/Wheel_back_left_1.stl" scale="0.001 0.001 0.001"/>
    </geometry>
  </collision>
</link>

<link name="Wheel_back_right_1">
  <inertial>
    <origin xyz="-2.7755575615628914e-17 -0.05000000000000001 0.0" rpy="0 0 0"/>
    <mass value="98.6460093227195"/>
    <inertia ixx="1.068665" iyy="1.97292" izz="1.068665" ixy="0.0" iyz="-0.0" ixz="0.0"/>
  </inertial>
  <visual>
    <origin xyz="-0.15 0.01 -0.15" rpy="0 0 0"/>
    <geometry>
      <mesh filename="file://$(find car)/meshes/Wheel_back_right_1.stl" scale="0.001 0.001 0.001"/>
    </geometry>
    <material name="silver"/>
  </visual>
  <collision>
    <origin xyz="-0.15 0.01 -0.15" rpy="0 0 0"/>
    <geometry>
      <mesh filename="file://$(find car)/meshes/Wheel_back_right_1.stl" scale="0.001 0.001 0.001"/>
    </geometry>
  </collision>
</link>

<link name="Laser_1">
  <inertial>
    <origin xyz="1.1102230246251565e-16 -2.7755575615628914e-17 0.015000000000000013" rpy="0 0 0"/>
    <mass value="7.398450699203962"/>
    <inertia ixx="0.019051" iyy="0.019051" izz="0.036992" ixy="0.0" iyz="0.0" ixz="0.0"/>
  </inertial>
  <visual>
    <origin xyz="-0.5 -0.25 -0.9" rpy="0 0 0"/>
    <geometry>
      <mesh filename="file://$(find car)/meshes/Laser_1.stl" scale="0.001 0.001 0.001"/>
    </geometry>
    <material name="silver"/>
  </visual>
  <collision>
    <origin xyz="-0.5 -0.25 -0.9" rpy="0 0 0"/>
    <geometry>
      <mesh filename="file://$(find car)/meshes/Laser_1.stl" scale="0.001 0.001 0.001"/>
    </geometry>
  </collision>
</link>

<link name="Camara_back_1">
  <inertial>
    <origin xyz="6.938893903907228e-17 -2.7755575615628914e-17 0.015000000000000013" rpy="0 0 0"/>
    <mass value="7.398450699203962"/>
    <inertia ixx="0.019051" iyy="0.019051" izz="0.036992" ixy="-0.0" iyz="0.0" ixz="-0.0"/>
  </inertial>
  <visual>
    <origin xyz="-0.1 -0.25 -0.54" rpy="0 0 0"/>
    <geometry>
      <mesh filename="file://$(find car)/meshes/Camara_back_1.stl" scale="0.001 0.001 0.001"/>
    </geometry>
    <material name="silver"/>
  </visual>
  <collision>
    <origin xyz="-0.1 -0.25 -0.54" rpy="0 0 0"/>
    <geometry>
      <mesh filename="file://$(find car)/meshes/Camara_back_1.stl" scale="0.001 0.001 0.001"/>
    </geometry>
  </collision>
</link>

<link name="Camara_left_1">
  <inertial>
    <origin xyz="-5.551115123125783e-17 0.0 0.015000000000000013" rpy="0 0 0"/>
    <mass value="7.398450699203962"/>
    <inertia ixx="0.019051" iyy="0.019051" izz="0.036992" ixy="0.0" iyz="0.0" ixz="0.0"/>
  </inertial>
  <visual>
    <origin xyz="-0.5 -0.45 -0.54" rpy="0 0 0"/>
    <geometry>
      <mesh filename="file://$(find car)/meshes/Camara_left_1.stl" scale="0.001 0.001 0.001"/>
    </geometry>
    <material name="silver"/>
  </visual>
  <collision>
    <origin xyz="-0.5 -0.45 -0.54" rpy="0 0 0"/>
    <geometry>
      <mesh filename="file://$(find car)/meshes/Camara_left_1.stl" scale="0.001 0.001 0.001"/>
    </geometry>
  </collision>
</link>

<link name="Camara_front_1">
  <inertial>
    <origin xyz="0.0 -2.7755575615628914e-17 0.015000000000000013" rpy="0 0 0"/>
    <mass value="7.398450699203962"/>
    <inertia ixx="0.019051" iyy="0.019051" izz="0.036992" ixy="0.0" iyz="0.0" ixz="0.0"/>
  </inertial>
  <visual>
    <origin xyz="-0.95 -0.25 -0.54" rpy="0 0 0"/>
    <geometry>
      <mesh filename="file://$(find car)/meshes/Camara_front_1.stl" scale="0.001 0.001 0.001"/>
    </geometry>
    <material name="silver"/>
  </visual>
  <collision>
    <origin xyz="-0.95 -0.25 -0.54" rpy="0 0 0"/>
    <geometry>
      <mesh filename="file://$(find car)/meshes/Camara_front_1.stl" scale="0.001 0.001 0.001"/>
    </geometry>
  </collision>
</link>

<link name="Camara_right_1">
  <inertial>
    <origin xyz="1.1102230246251565e-16 -1.3877787807814457e-17 0.015000000000000013" rpy="0 0 0"/>
    <mass value="7.398450699203962"/>
    <inertia ixx="0.019051" iyy="0.019051" izz="0.036992" ixy="0.0" iyz="0.0" ixz="0.0"/>
  </inertial>
  <visual>
    <origin xyz="-0.5 -0.05 -0.54" rpy="0 0 0"/>
    <geometry>
      <mesh filename="file://$(find car)/meshes/Camara_right_1.stl" scale="0.001 0.001 0.001"/>
    </geometry>
    <material name="silver"/>
  </visual>
  <collision>
    <origin xyz="-0.5 -0.05 -0.54" rpy="0 0 0"/>
    <geometry>
      <mesh filename="file://$(find car)/meshes/Camara_right_1.stl" scale="0.001 0.001 0.001"/>
    </geometry>
  </collision>
</link>

<joint name="revolute_right_wheel" type="continuous">
  <origin xyz="0.875 -0.01 0.15" rpy="0 0 0"/>
  <parent link="base_link"/>
  <child link="Wheel_front_right_1"/>
  <axis xyz="0.0 -1.0 0.0"/>
</joint>

<joint name="revolute_left_wheel" type="continuous">
  <origin xyz="0.875 0.51 0.15" rpy="0 0 0"/>
  <parent link="base_link"/>
  <child link="Wheel_front_left_1"/>
  <axis xyz="0.0 1.0 0.0"/>
</joint>

<joint name="revolute_back_left_wheel" type="continuous">
  <origin xyz="0.15 0.51 0.15" rpy="0 0 0"/>
  <parent link="base_link"/>
  <child link="Wheel_back_left_1"/>
  <axis xyz="0.0 1.0 0.0"/>
</joint>

<joint name="revolute_back_right_wheel" type="continuous">
  <origin xyz="0.15 -0.01 0.15" rpy="0 0 0"/>
  <parent link="base_link"/>
  <child link="Wheel_back_right_1"/>
  <axis xyz="0.0 -1.0 0.0"/>
</joint>

<joint name="revolute_laser" type="continuous">
  <origin xyz="0.5 0.25 0.9" rpy="0 0 0"/>
  <parent link="base_link"/>
  <child link="Laser_1"/>
  <axis xyz="0.0 0.0 1.0"/>
</joint>

<joint name="revolute_camara_back" type="continuous">
  <origin xyz="0.1 0.25 0.54" rpy="0 0 0"/>
  <parent link="base_link"/>
  <child link="Camara_back_1"/>
  <axis xyz="0.0 0.0 1.0"/>
</joint>

<joint name="revoute_camara_left" type="continuous">
  <origin xyz="0.5 0.45 0.54" rpy="0 0 0"/>
  <parent link="base_link"/>
  <child link="Camara_left_1"/>
  <axis xyz="0.0 0.0 1.0"/>
</joint>

<joint name="revolute_camara_front" type="continuous">
  <origin xyz="0.95 0.25 0.54" rpy="0 0 0"/>
  <parent link="base_link"/>
  <child link="Camara_front_1"/>
  <axis xyz="0.0 0.0 1.0"/>
</joint>

<link name="camera_optical_frame">
</link> 

<joint name="camera_optical_joint" type="fixed">
  <parent link="Camara_front_1"/>
  <child link="camera_optical_frame"/>
  <!-- Ajusta rpy para alinear el frame óptico -->
  <origin xyz="0 0 0" rpy="-1.5708 0 -1.5708"/>
</joint>

<joint name="revolute_camara_right" type="continuous">
  <origin xyz="0.5 0.05 0.54" rpy="0 0 0"/>
  <parent link="base_link"/>
  <child link="Camara_right_1"/>
  <axis xyz="0.0 0.0 1.0"/>
</joint>

</robot>
